Workbook

Sheet README
A1: Service Case Data — Weeks 1–8 (2026-08-31 to 2026-10-25)
A2: SYNTHETIC DATA. Generated for practice only. Not real ASML or customer data.
A4: Field definitions
A5: Case_ID — unique service case number
A6: Open_Date / Close_Date — date opened / closed (blank Close_Date = still open)
A7: Status — Open or Closed as of 2026-10-25
A8: Priority — P1 tool down / P2 performance degraded / P3 routine
A9: Case_Type — why the case was opened
A10: Customer_Site — which customer fab
A11: Owner — engineer responsible
A12: Delay_Reason — filled only when the case is (or was) past its SLA target
A14: SLA_Table sheet — target days to close for each priority
... A18: Do not edit the original Cases sheet — keep it as the raw source.

Sheet Cases
A1: Case_ID | B1: Open_Date | C1: Close_Date | D1: Status | E1: Priority | F1: Case_Type | G1: Customer_Site | H1: Owner | I1: Delay_Reason
A2: CS-1001 | B2: 46265 | C2: 46266 | D2: Closed | E2: P2 | F2: Customer inquiry | G2: Fab C | H2: Chen
A3: CS-1002 | B3: 46265 | C3: 46266 | D3: Closed | E3: P2 | F3: Unscheduled repair | G3: Fab A | H3: Liu
A4: CS-1003 | B4: 46265 | C4: 46271 | D4: Closed | E4: P3 | F4: Unscheduled repair | G4: Fab C | H4: Wang
A5: CS-1004 | B5: 46266 | C5: 46272 | D5: Closed | E5: P3 | F5: Software / upgrade | G5: Fab B | H5: Wang
A6: CS-1005 | B6: 46266 | C6: 46268 | D6: Closed | E6: P2 | F6: Part replacement | G6: Fab B | H6: Chen
A7: CS-1006 | B7: 46266 | C7: 46268 | D7: Closed | E7: P1 | F7: Customer inquiry | G7: Fab C | H7: Lin
A8: CS-1007 | B8: 46266 | C8: 46267 | D8: Closed | E8: P2 | F8: Unscheduled repair | G8: Fab C | H8: Liu
A9: CS-1008 | B9: 46266 | C9: 46266 | D9: Closed | E9: P1 | F9: Preventive maintenance | G9: Fab A | H9: Tsai
A10: CS-1009 | B10: 46267 | C10: 46271 | D10: Closed | E10: P2 | F10: Part replacement | G10: Fab A | H10: Liu
A11: CS-1010 | B11: 46267 | C11: 46272 | D11: Closed | E11: P2 | F11: Preventive maintenance | G11: Fab C | H11: Chen
A12: CS-1011 | B12: 46268 | C12: 46282 | D12: Closed | E12: P3 | F12: Customer inquiry | G12: Fab A | H12: Chen | I12: Waiting for customer
A13: CS-1012 | B13: 46268 | C13: 46283 | D13: Closed | E13: P3 | F13: Unscheduled repair | G13: Fab A | H13: Huang | I13: Waiting for parts
A14: CS-1013 | B14: 46268 | C14: 46271 | D14: Closed | E14: P1 | F14: Software / upgrade | G14: Fab C | H14: Huang | I14: Waiting for parts
A15: CS-1014 | B15: 46268 | C15: 46269 | D15: Closed | E15: P2 | F15: Unscheduled repair | G15: Fab A | H15: Wang
A16: CS-1015 | B16: 46268 | C16: 46279 | D16: Closed | E16: P3 | F16: Part replacement | G16: Fab B | H16: Wang | I16: Waiting for engineer
A17: CS-1016 | B17: 46268 | C17: 46269 | D17: Closed | E17: P2 | F17: Part replacement | G17: Fab A | H17: Huang
A18: CS-1017 | B18: 46269 | C18: 46269 | D18: Closed | E18: P1 | F18: Unscheduled repair | G18: Fab A | H18: Lin
A19: CS-1018 | B19: 46269 | C19: 46275 | D19: Closed | E19: P3 | F19: Customer inquiry | G19: Fab C | H19: Wang
A20: CS-1019 | B20: 46269 | C20: 46276 | D20: Closed | E20: P3 | F20: Part replacement | G20: Fab A | H20: Lin
A21: CS-1020 | B21: 46269 | C21: 46271 | D21: Closed | E21: P1 | F21: Customer inquiry | G21: Fab C | H21: Huang
A22: CS-1021 | B22: 46269 | C22: 46279 | D22: Closed | E22: P3 | F22: Part replacement | G22: Fab C | H22: Lin
A23: CS-1022 | B23: 46269 | C23: 46278 | D23: Closed | E23: P3 | F23: Unscheduled repair | G23: Fab A | H23: Wang
A24: CS-1023 | B24: 46269 | C24: 46274 | D24: Closed | E24: P2 | F24: Preventive maintenance | G24: Fab C | H24: Tsai
A25: CS-1024 | B25: 46270 | C25: 46279 | D25: Closed | E25: P3 | F25: Preventive maintenance | G25: Fab C | H25: Chen
A26: CS-1025 | B26: 46270 | C26: 46277 | D26: Closed | E26: P3 | F26: Unscheduled repair | G26: Fab B | H26: Lin
A27: CS-1026 | B27: 46270 | C27: 46278 | D27: Closed | E27: P2 | F27: Customer inquiry | G27: Fab A | H27: Wang | I27: Waiting for parts
A28: CS-1027 | B28: 46271 | C28: 46280 | D28: Closed | E28: P3 | F28: Preventive maintenance | G28: Fab C | H28: Tsai
A29: CS-1028 | B29: 46271 | C29: 46280 | D29: Closed | E29: P3 | F29: Customer inquiry | G29: Fab B | H29: Liu
A30: CS-1029 | B30: 46271 | C30: 46287 | D30: Closed | E30: P3 | F30: Unscheduled repair | G30: Fab A | H30: Chen | I30: Waiting for parts
A31: CS-1030 | B31: 46271 | C31: 46277 | D31: Closed | E31: P2 | F31: Customer inquiry | G31: Fab A | H31: Lin | I31: waiting parts
A32: CS-1031 | B32: 46272 | C32: 46280 | D32: Closed | E32: P3 | F32: Part replacement | G32: Fab A | H32: Wang
A33: CS-1032 | B33: 46272 | C33: 46278 | D33: Closed | E33: P3 | F33: Part replacement | G33: Fab C | H33: Lin
A34: CS-1033 | B34: 46272 | C34: 46276 | D34: Closed | E34: P2 | F34: Part replacement | G34: Fab A | H34: Tsai
A35: CS-1034 | B35: 46272 | C35: 46277 | D35: Closed | E35: P2 | F35: Part replacement | G35: Fab B | H35: Liu
A36: CS-1035 | B36: 46272 | C36: 46273 | D36: Closed | E36: P1 | F36: Customer inquiry | G36: Fab A | H36: Lin
A37: CS-1036 | B37: 46272 | C37: 46273 | D37: Closed | E37: P1 | F37: Unscheduled repair | G37: Fab C | H37: Wang
A38: CS-1037 | B38: 46273 | C38: 46288 | D38: Closed | E38: P3 | F38: Customer inquiry | G38: Fab B | H38: Chen | I38: Escalated
A39: CS-1038 | B39: 46273 | C39: 46280 | D39: Closed | E39: P3 | F39: Customer inquiry | G39: Fab B | H39: Huang
A40: CS-1039 | B40: 46273 | C40: 46277 | D40: Closed | E40: P2 | F40: Part replacement | G40: Fab A | H40: Tsai
...

Sheet SLA_Table
A1: Priority | B1: Target_Days | C1: Meaning
A2: P1 | B2: 2 | C2: Tool down
A3: P2 | B3: 5 | C3: Performance degraded
A4: P3 | B4: 10 | C4: Routine / inquiry
A6: Assumption: SLA targets are illustrative, set for this practice dataset.

Sheet KPI
A3: 列標籤 | B3: 計數 - Case_ID | E3: 週 | F3: 開案數 | G3: 結案數 | H3: 準時結案率 | I3: 平均處理天數 | K3: 目前未結案件數 | M3: 優先度 | N3: 準時 | O3: 逾期 | P3: 準時結案率
A4: 8月31日 | B4: 30 | E4: 46265 | F4: =COUNTIFS(Cases_Tbl[Open_Week],E4) -> 30 | G4: =COUNTIFS(Cases_Tbl[Close_Week],E4) -> 13 | H4: =IFERROR(COUNTIFS(Cases_Tbl[Close_Week],E4,Cases_Tbl[On_Time],"Yes")/(COUNTIFS(Cases_Tbl[Close_Week],E4,Cases_Tbl[On_Time],"Yes")+COUNTIFS(Cases_Tbl[Close_Week],E4,Cases_Tbl[On_Time],"No")),"") -> 0.92307692 | I4: =IFERROR(AVERAGEIFS(Cases_Tbl[Days_to_Close],Cases_Tbl[Close_Week],E4),"") -> 1.8461538 | K4: =COUNTIF(Cases_Tbl[Status],"Open") -> 43 | M4: P1 | N4: =COUNTIFS(Cases_Tbl[Priority],M4,Cases_Tbl[On_Time],"Yes") -> 46 | O4: =COUNTIFS(Cases_Tbl[Priority],M4,Cases_Tbl[On_Time],"No") -> 9 | P4: =N4/(N4+O4) -> 0.83636364
A5: 9月7日 | B5: 37 | E5: 46272 | F5: =COUNTIFS(Cases_Tbl[Open_Week],E5) -> 37 | G5: =COUNTIFS(Cases_Tbl[Close_Week],E5) -> 24 | H5: =IFERROR(COUNTIFS(Cases_Tbl[Close_Week],E5,Cases_Tbl[On_Time],"Yes")/(COUNTIFS(Cases_Tbl[Close_Week],E5,Cases_Tbl[On_Time],"Yes")+COUNTIFS(Cases_Tbl[Close_Week],E5,Cases_Tbl[On_Time],"No")),"") -> 0.91666667 | I5: =IFERROR(AVERAGEIFS(Cases_Tbl[Days_to_Close],Cases_Tbl[Close_Week],E5),"") -> 3.7083333 | M5: P2 | N5: =COUNTIFS(Cases_Tbl[Priority],M5,Cases_Tbl[On_Time],"Yes") -> 89 | O5: =COUNTIFS(Cases_Tbl[Priority],M5,Cases_Tbl[On_Time],"No") -> 20 | P5: =N5/(N5+O5) -> 0.81651376
A6: 9月14日 | B6: 40 | E6: 46279 | F6: =COUNTIFS(Cases_Tbl[Open_Week],E6) -> 40 | G6: =COUNTIFS(Cases_Tbl[Close_Week],E6) -> 31 | H6: =IFERROR(COUNTIFS(Cases_Tbl[Close_Week],E6,Cases_Tbl[On_Time],"Yes")/(COUNTIFS(Cases_Tbl[Close_Week],E6,Cases_Tbl[On_Time],"Yes")+COUNTIFS(Cases_Tbl[Close_Week],E6,Cases_Tbl[On_Time],"No")),"") -> 0.74193548 | I6: =IFERROR(AVERAGEIFS(Cases_Tbl[Days_to_Close],Cases_Tbl[Close_Week],E6),"") -> 6.3225806 | K6: 整體準時結案率 | M6: P3 | N6: =COUNTIFS(Cases_Tbl[Priority],M6,Cases_Tbl[On_Time],"Yes") -> 76 | O6: =COUNTIFS(Cases_Tbl[Priority],M6,Cases_Tbl[On_Time],"No") -> 19 | P6: =N6/(N6+O6) -> 0.8
A7: 9月21日 | B7: 30 | E7: 46286 | F7: =COUNTIFS(Cases_Tbl[Open_Week],E7) -> 30 | G7: =COUNTIFS(Cases_Tbl[Close_Week],E7) -> 43 | H7: =IFERROR(COUNTIFS(Cases_Tbl[Close_Week],E7,Cases_Tbl[On_Time],"Yes")/(COUNTIFS(Cases_Tbl[Close_Week],E7,Cases_Tbl[On_Time],"Yes")+COUNTIFS(Cases_Tbl[Close_Week],E7,Cases_Tbl[On_Time],"No")),"") -> 0.86046512 | I7: =IFERROR(AVERAGEIFS(Cases_Tbl[Days_to_Close],Cases_Tbl[Close_Week],E7),"") -> 6.372093 | K7: =COUNTIF(Cases_Tbl[On_Time],"Yes")/(COUNTIF(Cases_Tbl[On_Time],"Yes")+COUNTIF(Cases_Tbl[On_Time],"No")) -> 0.81467181
A8: 9月28日 | B8: 41 | E8: 46293 | F8: =COUNTIFS(Cases_Tbl[Open_Week],E8) -> 41 | G8: =COUNTIFS(Cases_Tbl[Close_Week],E8) -> 41 | H8: =IFERROR(COUNTIFS(Cases_Tbl[Close_Week],E8,Cases_Tbl[On_Time],"Yes")/(COUNTIFS(Cases_Tbl[Close_Week],E8,Cases_Tbl[On_Time],"Yes")+COUNTIFS(Cases_Tbl[Close_Week],E8,Cases_Tbl[On_Time],"No")),"") -> 0.75 | I8: =IFERROR(AVERAGEIFS(Cases_Tbl[Days_to_Close],Cases_Tbl[Close_Week],E8),"") -> 5.175 | K8: 整體平均處理天數
A9: 10月5日 | B9: 38 | E9: 46300 | F9: =COUNTIFS(Cases_Tbl[Open_Week],E9) -> 38 | G9: =COUNTIFS(Cases_Tbl[Close_Week],E9) -> 33 | H9: =IFERROR(COUNTIFS(Cases_Tbl[Close_Week],E9,Cases_Tbl[On_Time],"Yes")/(COUNTIFS(Cases_Tbl[Close_Week],E9,Cases_Tbl[On_Time],"Yes")+COUNTIFS(Cases_Tbl[Close_Week],E9,Cases_Tbl[On_Time],"No")),"") -> 0.78125 | I9: =IFERROR(AVERAGEIFS(Cases_Tbl[Days_to_Close],Cases_Tbl[Close_Week],E9),"") -> 4.65625 | K9: =AVERAGE(Cases_Tbl[Days_to_Close]) -> 5.2316602 | M9: 案齡 | N9: 件數
A10: 10月12日 | B10: 44 | E10: 46307 | F10: =COUNTIFS(Cases_Tbl[Open_Week],E10) -> 44 | G10: =COUNTIFS(Cases_Tbl[Close_Week],E10) -> 39 | H10: =IFERROR(COUNTIFS(Cases_Tbl[Close_Week],E10,Cases_Tbl[On_Time],"Yes")/(COUNTIFS(Cases_Tbl[Close_Week],E10,Cases_Tbl[On_Time],"Yes")+COUNTIFS(Cases_Tbl[Close_Week],E10,Cases_Tbl[On_Time],"No")),"") -> 0.84210526 | I10: =IFERROR(AVERAGEIFS(Cases_Tbl[Days_to_Close],Cases_Tbl[Close_Week],E10),"") -> 5.4210526 | M10: 0–2 天 | N10: =COUNTIFS(Cases_Tbl[Age_Days],">=0",Cases_Tbl[Age_Days],"<=2") -> 2
A11: 10月19日 | B11: 40 | E11: 46314 | F11: =COUNTIFS(Cases_Tbl[Open_Week],E11) -> 40 | G11: =COUNTIFS(Cases_Tbl[Close_Week],E11) -> 36 | H11: =IFERROR(COUNTIFS(Cases_Tbl[Close_Week],E11,Cases_Tbl[On_Time],"Yes")/(COUNTIFS(Cases_Tbl[Close_Week],E11,Cases_Tbl[On_Time],"Yes")+COUNTIFS(Cases_Tbl[Close_Week],E11,Cases_Tbl[On_Time],"No")),"") -> 0.77777778 | I11: =IFERROR(AVERAGEIFS(Cases_Tbl[Days_to_Close],Cases_Tbl[Close_Week],E11),"") -> 5.7222222 | M11: 3–5 天 | N11: =COUNTIFS(Cases_Tbl[Age_Days],">=3",Cases_Tbl[Age_Days],"<=5") -> 8
A12: 10月26日 | B12: 5 | E12: 46321 | F12: =COUNTIFS(Cases_Tbl[Open_Week],E12) -> 5 | G12: =COUNTIFS(Cases_Tbl[Close_Week],E12) -> 2 | H12: =IFERROR(COUNTIFS(Cases_Tbl[Close_Week],E12,Cases_Tbl[On_Time],"Yes")/(COUNTIFS(Cases_Tbl[Close_Week],E12,Cases_Tbl[On_Time],"Yes")+COUNTIFS(Cases_Tbl[Close_Week],E12,Cases_Tbl[On_Time],"No")),"") -> 1 | I12: =IFERROR(AVERAGEIFS(Cases_Tbl[Days_to_Close],Cases_Tbl[Close_Week],E12),"") -> 2 | K12: 資料截止日 | M12: 6–10 天 | N12: =COUNTIFS(Cases_Tbl[Age_Days],">=6",Cases_Tbl[Age_Days],"<=10") -> 20
A13: 總計 | B13: 305 | K13: 46325 | M13: 超過 10 天 | N13: =COUNTIFS(Cases_Tbl[Age_Days],">10") -> 13
M14: 已超過目標天數 | N14: =COUNTIF(Cases_Tbl[Over_Target],"Yes") -> 20
A21: 列標籤 | B21: 計數 - Case_ID | C21: 計數 - Case_ID2
A22: Waiting for parts | B22: 32 | C22: 0.58181818
A23: Waiting for customer | B23: 9 | C23: 0.16363636
A24: Waiting for engineer | B24: 8 | C24: 0.14545455
A25: Escalated to tech support | B25: 6 | C25: 0.10909091
A26: 總計 | B26: 55 | C26: 1

Sheet Cases_Clean
A1: Case_ID | B1: Open_Date | C1: Close_Date | D1: Status | E1: Priority | F1: Case_Type | G1: Customer_Site | H1: Owner | I1: Delay_Reason | J1: Data_Flag | K1: Target_Days | L1: Days_to_Close | M1: On_Time | N1: Open_Week | O1: Close_Week | P1: Age_Days | Q1: Over_Target
A2: CS-1001 | B2: 46265 | C2: 46266 | D2: Closed | E2: P2 | F2: Customer inquiry | G2: Fab C | H2: Chen | K2: =_xlfn.XLOOKUP(Cases_Tbl[[#This Row],[Priority]],SLA_Table!$A$2:$A$4,SLA_Table!$B$2:$B$4) -> 5 | L2: =IF(OR(C2="",J2<>""),"",C2-B2) -> 1 | M2: =IF(L2="","",IF(L2<=K2,"Yes","No")) -> Yes | N2: =B2-WEEKDAY(B2,2)+1 -> 46265 | O2: =IF(C2="","",C2-WEEKDAY(C2,2)+1) -> 46265 | P2: =IF(D2="Open",KPI!$K$13-B2,"") | Q2: =IF(P2="","",IF(P2>K2,"Yes","No"))
A3: CS-1002 | B3: 46265 | C3: 46266 | D3: Closed | E3: P2 | F3: Unscheduled repair | G3: Fab A | H3: Liu | K3: =_xlfn.XLOOKUP(Cases_Tbl[[#This Row],[Priority]],SLA_Table!$A$2:$A$4,SLA_Table!$B$2:$B$4) -> 5 | L3: =IF(OR(C3="",J3<>""),"",C3-B3) -> 1 | M3: =IF(L3="","",IF(L3<=K3,"Yes","No")) -> Yes | N3: =B3-WEEKDAY(B3,2)+1 -> 46265 | O3: =IF(C3="","",C3-WEEKDAY(C3,2)+1) -> 46265 | P3: =IF(D3="Open",KPI!$K$13-B3,"") | Q3: =IF(P3="","",IF(P3>K3,"Yes","No"))
A4: CS-1003 | B4: 46265 | C4: 46271 | D4: Closed | E4: P3 | F4: Unscheduled repair | G4: Fab C | H4: Wang | K4: =_xlfn.XLOOKUP(Cases_Tbl[[#This Row],[Priority]],SLA_Table!$A$2:$A$4,SLA_Table!$B$2:$B$4) -> 10 | L4: =IF(OR(C4="",J4<>""),"",C4-B4) -> 6 | M4: =IF(L4="","",IF(L4<=K4,"Yes","No")) -> Yes | N4: =B4-WEEKDAY(B4,2)+1 -> 46265 | O4: =IF(C4="","",C4-WEEKDAY(C4,2)+1) -> 46265 | P4: =IF(D4="Open",KPI!$K$13-B4,"") | Q4: =IF(P4="","",IF(P4>K4,"Yes","No"))
A5: CS-1004 | B5: 46266 | C5: 46272 | D5: Closed | E5: P3 | F5: Software / upgrade | G5: Fab B | H5: Wang | K5: =_xlfn.XLOOKUP(Cases_Tbl[[#This Row],[Priority]],SLA_Table!$A$2:$A$4,SLA_Table!$B$2:$B$4) -> 10 | L5: =IF(OR(C5="",J5<>""),"",C5-B5) -> 6 | M5: =IF(L5="","",IF(L5<=K5,"Yes","No")) -> Yes | N5: =B5-WEEKDAY(B5,2)+1 -> 46265 | O5: =IF(C5="","",C5-WEEKDAY(C5,2)+1) -> 46272 | P5: =IF(D5="Open",KPI!$K$13-B5,"") | Q5: =IF(P5="","",IF(P5>K5,"Yes","No"))
A6: CS-1005 | B6: 46266 | C6: 46268 | D6: Closed | E6: P2 | F6: Part replacement | G6: Fab B | H6: Chen | K6: =_xlfn.XLOOKUP(Cases_Tbl[[#This Row],[Priority]],SLA_Table!$A$2:$A$4,SLA_Table!$B$2:$B$4) -> 5 | L6: =IF(OR(C6="",J6<>""),"",C6-B6) -> 2 | M6: =IF(L6="","",IF(L6<=K6,"Yes","No")) -> Yes | N6: =B6-WEEKDAY(B6,2)+1 -> 46265 | O6: =IF(C6="","",C6-WEEKDAY(C6,2)+1) -> 46265 | P6: =IF(D6="Open",KPI!$K$13-B6,"") | Q6: =IF(P6="","",IF(P6>K6,"Yes","No"))
A7: CS-1006 | B7: 46266 | C7: 46268 | D7: Closed | E7: P1 | F7: Customer inquiry | G7: Fab C | H7: Lin | K7: =_xlfn.XLOOKUP(Cases_Tbl[[#This Row],[Priority]],SLA_Table!$A$2:$A$4,SLA_Table!$B$2:$B$4) -> 2 | L7: =IF(OR(C7="",J7<>""),"",C7-B7) -> 2 | M7: =IF(L7="","",IF(L7<=K7,"Yes","No")) -> Yes | N7: =B7-WEEKDAY(B7,2)+1 -> 46265 | O7: =IF(C7="","",C7-WEEKDAY(C7,2)+1) -> 46265 | P7: =IF(D7="Open",KPI!$K$13-B7,"") | Q7: =IF(P7="","",IF(P7>K7,"Yes","No"))
A8: CS-1007 | B8: 46266 | C8: 46267 | D8: Closed | E8: P2 | F8: Unscheduled repair | G8: Fab C | H8: Liu | K8: =_xlfn.XLOOKUP(Cases_Tbl[[#This Row],[Priority]],SLA_Table!$A$2:$A$4,SLA_Table!$B$2:$B$4) -> 5 | L8: =IF(OR(C8="",J8<>""),"",C8-B8) -> 1 | M8: =IF(L8="","",IF(L8<=K8,"Yes","No")) -> Yes | N8: =B8-WEEKDAY(B8,2)+1 -> 46265 | O8: =IF(C8="","",C8-WEEKDAY(C8,2)+1) -> 46265 | P8: =IF(D8="Open",KPI!$K$13-B8,"") | Q8: =IF(P8="","",IF(P8>K8,"Yes","No"))
A9: CS-1008 | B9: 46266 | C9: 46266 | D9: Closed | E9: P1 | F9: Preventive maintenance | G9: Fab A | H9: Tsai | K9: =_xlfn.XLOOKUP(Cases_Tbl[[#This Row],[Priority]],SLA_Table!$A$2:$A$4,SLA_Table!$B$2:$B$4) -> 2 | L9: =IF(OR(C9="",J9<>""),"",C9-B9) -> 0 | M9: =IF(L9="","",IF(L9<=K9,"Yes","No")) -> Yes | N9: =B9-WEEKDAY(B9,2)+1 -> 46265 | O9: =IF(C9="","",C9-WEEKDAY(C9,2)+1) -> 46265 | P9: =IF(D9="Open",KPI!$K$13-B9,"") | Q9: =IF(P9="","",IF(P9>K9,"Yes","No"))
A10: CS-1009 | B10: 46267 | C10: 46271 | D10: Closed | E10: P2 | F10: Part replacement | G10: Fab A | H10: Liu | K10: =_xlfn.XLOOKUP(Cases_Tbl[[#This Row],[Priority]],SLA_Table!$A$2:$A$4,SLA_Table!$B$2:$B$4) -> 5 | L10: =IF(OR(C10="",J10<>""),"",C10-B10) -> 4 | M10: =IF(L10="","",IF(L10<=K10,"Yes","No")) -> Yes | N10: =B10-WEEKDAY(B10,2)+1 -> 46265 | O10: =IF(C10="","",C10-WEEKDAY(C10,2)+1) -> 46265 | P10: =IF(D10="Open",KPI!$K$13-B10,"") | Q10: =IF(P10="","",IF(P10>K10,"Yes","No"))
A11: CS-1010 | B11: 46267 | C11: 46272 | D11: Closed | E11: P2 | F11: Preventive maintenance | G11: Fab C | H11: Chen | K11: =_xlfn.XLOOKUP(Cases_Tbl[[#This Row],[Priority]],SLA_Table!$A$2:$A$4,SLA_Table!$B$2:$B$4) -> 5 | L11: =IF(OR(C11="",J11<>""),"",C11-B11) -> 5 | M11: =IF(L11="","",IF(L11<=K11,"Yes","No")) -> Yes | N11: =B11-WEEKDAY(B11,2)+1 -> 46265 | O11: =IF(C11="","",C11-WEEKDAY(C11,2)+1) -> 46272 | P11: =IF(D11="Open",KPI!$K$13-B11,"") | Q11: =IF(P11="","",IF(P11>K11,"Yes","No"))
A12: CS-1011 | B12: 46268 | C12: 46282 | D12: Closed | E12: P3 | F12: Customer inquiry | G12: Fab A | H12: Chen | I12: Waiting for customer | K12: =_xlfn.XLOOKUP(Cases_Tbl[[#This Row],[Priority]],SLA_Table!$A$2:$A$4,SLA_Table!$B$2:$B$4) -> 10 | L12: =IF(OR(C12="",J12<>""),"",C12-B12) -> 14 | M12: =IF(L12="","",IF(L12<=K12,"Yes","No")) -> No | N12: =B12-WEEKDAY(B12,2)+1 -> 46265 | O12: =IF(C12="","",C12-WEEKDAY(C12,2)+1) -> 46279 | P12: =IF(D12="Open",KPI!$K$13-B12,"") | Q12: =IF(P12="","",IF(P12>K12,"Yes","No"))
A13: CS-1012 | B13: 46268 | C13: 46283 | D13: Closed | E13: P3 | F13: Unscheduled repair | G13: Fab A | H13: Huang | I13: Waiting for parts | K13: =_xlfn.XLOOKUP(Cases_Tbl[[#This Row],[Priority]],SLA_Table!$A$2:$A$4,SLA_Table!$B$2:$B$4) -> 10 | L13: =IF(OR(C13="",J13<>""),"",C13-B13) -> 15 | M13: =IF(L13="","",IF(L13<=K13,"Yes","No")) -> No | N13: =B13-WEEKDAY(B13,2)+1 -> 46265 | O13: =IF(C13="","",C13-WEEKDAY(C13,2)+1) -> 46279 | P13: =IF(D13="Open",KPI!$K$13-B13,"") | Q13: =IF(P13="","",IF(P13>K13,"Yes","No"))
A14: CS-1013 | B14: 46268 | C14: 46271 | D14: Closed | E14: P1 | F14: Software / upgrade | G14: Fab C | H14: Huang | I14: Waiting for parts | K14: =_xlfn.XLOOKUP(Cases_Tbl[[#This Row],[Priority]],SLA_Table!$A$2:$A$4,SLA_Table!$B$2:$B$4) -> 2 | L14: =IF(OR(C14="",J14<>""),"",C14-B14) -> 3 | M14: =IF(L14="","",IF(L14<=K14,"Yes","No")) -> No | N14: =B14-WEEKDAY(B14,2)+1 -> 46265 | O14: =IF(C14="","",C14-WEEKDAY(C14,2)+1) -> 46265 | P14: =IF(D14="Open",KPI!$K$13-B14,"") | Q14: =IF(P14="","",IF(P14>K14,"Yes","No"))
A15: CS-1014 | B15: 46268 | C15: 46269 | D15: Closed | E15: P2 | F15: Unscheduled repair | G15: Fab A | H15: Wang | K15: =_xlfn.XLOOKUP(Cases_Tbl[[#This Row],[Priority]],SLA_Table!$A$2:$A$4,SLA_Table!$B$2:$B$4) -> 5 | L15: =IF(OR(C15="",J15<>""),"",C15-B15) -> 1 | M15: =IF(L15="","",IF(L15<=K15,"Yes","No")) -> Yes | N15: =B15-WEEKDAY(B15,2)+1 -> 46265 | O15: =IF(C15="","",C15-WEEKDAY(C15,2)+1) -> 46265 | P15: =IF(D15="Open",KPI!$K$13-B15,"") | Q15: =IF(P15="","",IF(P15>K15,"Yes","No"))
A16: CS-1015 | B16: 46268 | C16: 46279 | D16: Closed | E16: P3 | F16: Part replacement | G16: Fab B | H16: Wang | I16: Waiting for engineer | K16: =_xlfn.XLOOKUP(Cases_Tbl[[#This Row],[Priority]],SLA_Table!$A$2:$A$4,SLA_Table!$B$2:$B$4) -> 10 | L16: =IF(OR(C16="",J16<>""),"",C16-B16) -> 11 | M16: =IF(L16="","",IF(L16<=K16,"Yes","No")) -> No | N16: =B16-WEEKDAY(B16,2)+1 -> 46265 | O16: =IF(C16="","",C16-WEEKDAY(C16,2)+1) -> 46279 | P16: =IF(D16="Open",KPI!$K$13-B16,"") | Q16: =IF(P16="","",IF(P16>K16,"Yes","No"))
A17: CS-1016 | B17: 46268 | C17: 46269 | D17: Closed | E17: P2 | F17: Part replacement | G17: Fab A | H17: Huang | K17: =_xlfn.XLOOKUP(Cases_Tbl[[#This Row],[Priority]],SLA_Table!$A$2:$A$4,SLA_Table!$B$2:$B$4) -> 5 | L17: =IF(OR(C17="",J17<>""),"",C17-B17) -> 1 | M17: =IF(L17="","",IF(L17<=K17,"Yes","No")) -> Yes | N17: =B17-WEEKDAY(B17,2)+1 -> 46265 | O17: =IF(C17="","",C17-WEEKDAY(C17,2)+1) -> 46265 | P17: =IF(D17="Open",KPI!$K$13-B17,"") | Q17: =IF(P17="","",IF(P17>K17,"Yes","No"))
A18: CS-1017 | B18: 46269 | C18: 46269 | D18: Closed | E18: P1 | F18: Unscheduled repair | G18: Fab A | H18: Lin | K18: =_xlfn.XLOOKUP(Cases_Tbl[[#This Row],[Priority]],SLA_Table!$A$2:$A$4,SLA_Table!$B$2:$B$4) -> 2 | L18: =IF(OR(C18="",J18<>""),"",C18-B18) -> 0 | M18: =IF(L18="","",IF(L18<=K18,"Yes","No")) -> Yes | N18: =B18-WEEKDAY(B18,2)+1 -> 46265 | O18: =IF(C18="","",C18-WEEKDAY(C18,2)+1) -> 46265 | P18: =IF(D18="Open",KPI!$K$13-B18,"") | Q18: =IF(P18="","",IF(P18>K18,"Yes","No"))
A19: CS-1018 | B19: 46269 | C19: 46275 | D19: Closed | E19: P3 | F19: Customer inquiry | G19: Fab C | H19: Wang | K19: =_xlfn.XLOOKUP(Cases_Tbl[[#This Row],[Priority]],SLA_Table!$A$2:$A$4,SLA_Table!$B$2:$B$4) -> 10 | L19: =IF(OR(C19="",J19<>""),"",C19-B19) -> 6 | M19: =IF(L19="","",IF(L19<=K19,"Yes","No")) -> Yes | N19: =B19-WEEKDAY(B19,2)+1 -> 46265 | O19: =IF(C19="","",C19-WEEKDAY(C19,2)+1) -> 46272 | P19: =IF(D19="Open",KPI!$K$13-B19,"") | Q19: =IF(P19="","",IF(P19>K19,"Yes","No"))
A20: CS-1019 | B20: 46269 | C20: 46276 | D20: Closed | E20: P3 | F20: Part replacement | G20: Fab A | H20: Lin | K20: =_xlfn.XLOOKUP(Cases_Tbl[[#This Row],[Priority]],SLA_Table!$A$2:$A$4,SLA_Table!$B$2:$B$4) -> 10 | L20: =IF(OR(C20="",J20<>""),"",C20-B20) -> 7 | M20: =IF(L20="","",IF(L20<=K20,"Yes","No")) -> Yes | N20: =B20-WEEKDAY(B20,2)+1 -> 46265 | O20: =IF(C20="","",C20-WEEKDAY(C20,2)+1) -> 46272 | P20: =IF(D20="Open",KPI!$K$13-B20,"") | Q20: =IF(P20="","",IF(P20>K20,"Yes","No"))
A21: CS-1020 | B21: 46269 | C21: 46271 | D21: Closed | E21: P1 | F21: Customer inquiry | G21: Fab C | H21: Huang | K21: =_xlfn.XLOOKUP(Cases_Tbl[[#This Row],[Priority]],SLA_Table!$A$2:$A$4,SLA_Table!$B$2:$B$4) -> 2 | L21: =IF(OR(C21="",J21<>""),"",C21-B21) -> 2 | M21: =IF(L21="","",IF(L21<=K21,"Yes","No")) -> Yes | N21: =B21-WEEKDAY(B21,2)+1 -> 46265 | O21: =IF(C21="","",C21-WEEKDAY(C21,2)+1) -> 46265 | P21: =IF(D21="Open",KPI!$K$13-B21,"") | Q21: =IF(P21="","",IF(P21>K21,"Yes","No"))
A22: CS-1021 | B22: 46269 | C22: 46279 | D22: Closed | E22: P3 | F22: Part replacement | G22: Fab C | H22: Lin | K22: =_xlfn.XLOOKUP(Cases_Tbl[[#This Row],[Priority]],SLA_Table!$A$2:$A$4,SLA_Table!$B$2:$B$4) -> 10 | L22: =IF(OR(C22="",J22<>""),"",C22-B22) -> 10 | M22: =IF(L22="","",IF(L22<=K22,"Yes","No")) -> Yes | N22: =B22-WEEKDAY(B22,2)+1 -> 46265 | O22: =IF(C22="","",C22-WEEKDAY(C22,2)+1) -> 46279 | P22: =IF(D22="Open",KPI!$K$13-B22,"") | Q22: =IF(P22="","",IF(P22>K22,"Yes","No"))
A23: CS-1022 | B23: 46269 | C23: 46278 | D23: Closed | E23: P3 | F23: Unscheduled repair | G23: Fab A | H23: Wang | K23: =_xlfn.XLOOKUP(Cases_Tbl[[#This Row],[Priority]],SLA_Table!$A$2:$A$4,SLA_Table!$B$2:$B$4) -> 10 | L23: =IF(OR(C23="",J23<>""),"",C23-B23) -> 9 | M23: =IF(L23="","",IF(L23<=K23,"Yes","No")) -> Yes | N23: =B23-WEEKDAY(B23,2)+1 -> 46265 | O23: =IF(C23="","",C23-WEEKDAY(C23,2)+1) -> 46272 | P23: =IF(D23="Open",KPI!$K$13-B23,"") | Q23: =IF(P23="","",IF(P23>K23,"Yes","No"))
A24: CS-1023 | B24: 46269 | C24: 46274 | D24: Closed | E24: P2 | F24: Preventive maintenance | G24: Fab C | H24: Tsai | K24: =_xlfn.XLOOKUP(Cases_Tbl[[#This Row],[Priority]],SLA_Table!$A$2:$A$4,SLA_Table!$B$2:$B$4) -> 5 | L24: =IF(OR(C24="",J24<>""),"",C24-B24) -> 5 | M24: =IF(L24="","",IF(L24<=K24,"Yes","No")) -> Yes | N24: =B24-WEEKDAY(B24,2)+1 -> 46265 | O24: =IF(C24="","",C24-WEEKDAY(C24,2)+1) -> 46272 | P24: =IF(D24="Open",KPI!$K$13-B24,"") | Q24: =IF(P24="","",IF(P24>K24,"Yes","No"))
A25: CS-1024 | B25: 46270 | C25: 46279 | D25: Closed | E25: P3 | F25: Preventive maintenance | G25: Fab C | H25: Chen | K25: =_xlfn.XLOOKUP(Cases_Tbl[[#This Row],[Priority]],SLA_Table!$A$2:$A$4,SLA_Table!$B$2:$B$4) -> 10 | L25: =IF(OR(C25="",J25<>""),"",C25-B25) -> 9 | M25: =IF(L25="","",IF(L25<=K25,"Yes","No")) -> Yes | N25: =B25-WEEKDAY(B25,2)+1 -> 46265 | O25: =IF(C25="","",C25-WEEKDAY(C25,2)+1) -> 46279 | P25: =IF(D25="Open",KPI!$K$13-B25,"") | Q25: =IF(P25="","",IF(P25>K25,"Yes","No"))
A26: CS-1025 | B26: 46270 | C26: 46277 | D26: Closed | E26: P3 | F26: Unscheduled repair | G26: Fab B | H26: Lin | K26: =_xlfn.XLOOKUP(Cases_Tbl[[#This Row],[Priority]],SLA_Table!$A$2:$A$4,SLA_Table!$B$2:$B$4) -> 10 | L26: =IF(OR(C26="",J26<>""),"",C26-B26) -> 7 | M26: =IF(L26="","",IF(L26<=K26,"Yes","No")) -> Yes | N26: =B26-WEEKDAY(B26,2)+1 -> 46265 | O26: =IF(C26="","",C26-WEEKDAY(C26,2)+1) -> 46272 | P26: =IF(D26="Open",KPI!$K$13-B26,"") | Q26: =IF(P26="","",IF(P26>K26,"Yes","No"))
A27: CS-1026 | B27: 46270 | C27: 46278 | D27: Closed | E27: P2 | F27: Customer inquiry | G27: Fab A | H27: Wang | I27: Waiting for parts | K27: =_xlfn.XLOOKUP(Cases_Tbl[[#This Row],[Priority]],SLA_Table!$A$2:$A$4,SLA_Table!$B$2:$B$4) -> 5 | L27: =IF(OR(C27="",J27<>""),"",C27-B27) -> 8 | M27: =IF(L27="","",IF(L27<=K27,"Yes","No")) -> No | N27: =B27-WEEKDAY(B27,2)+1 -> 46265 | O27: =IF(C27="","",C27-WEEKDAY(C27,2)+1) -> 46272 | P27: =IF(D27="Open",KPI!$K$13-B27,"") | Q27: =IF(P27="","",IF(P27>K27,"Yes","No"))
A28: CS-1027 | B28: 46271 | C28: 46280 | D28: Closed | E28: P3 | F28: Preventive maintenance | G28: Fab C | H28: Tsai | K28: =_xlfn.XLOOKUP(Cases_Tbl[[#This Row],[Priority]],SLA_Table!$A$2:$A$4,SLA_Table!$B$2:$B$4) -> 10 | L28: =IF(OR(C28="",J28<>""),"",C28-B28) -> 9 | M28: =IF(L28="","",IF(L28<=K28,"Yes","No")) -> Yes | N28: =B28-WEEKDAY(B28,2)+1 -> 46265 | O28: =IF(C28="","",C28-WEEKDAY(C28,2)+1) -> 46279 | P28: =IF(D28="Open",KPI!$K$13-B28,"") | Q28: =IF(P28="","",IF(P28>K28,"Yes","No"))
A29: CS-1028 | B29: 46271 | C29: 46280 | D29: Closed | E29: P3 | F29: Customer inquiry | G29: Fab B | H29: Liu | K29: =_xlfn.XLOOKUP(Cases_Tbl[[#This Row],[Priority]],SLA_Table!$A$2:$A$4,SLA_Table!$B$2:$B$4) -> 10 | L29: =IF(OR(C29="",J29<>""),"",C29-B29) -> 9 | M29: =IF(L29="","",IF(L29<=K29,"Yes","No")) -> Yes | N29: =B29-WEEKDAY(B29,2)+1 -> 46265 | O29: =IF(C29="","",C29-WEEKDAY(C29,2)+1) -> 46279 | P29: =IF(D29="Open",KPI!$K$13-B29,"") | Q29: =IF(P29="","",IF(P29>K29,"Yes","No"))
A30: CS-1029 | B30: 46271 | C30: 46287 | D30: Closed | E30: P3 | F30: Unscheduled repair | G30: Fab A | H30: Chen | I30: Waiting for parts | K30: =_xlfn.XLOOKUP(Cases_Tbl[[#This Row],[Priority]],SLA_Table!$A$2:$A$4,SLA_Table!$B$2:$B$4) -> 10 | L30: =IF(OR(C30="",J30<>""),"",C30-B30) -> 16 | M30: =IF(L30="","",IF(L30<=K30,"Yes","No")) -> No | N30: =B30-WEEKDAY(B30,2)+1 -> 46265 | O30: =IF(C30="","",C30-WEEKDAY(C30,2)+1) -> 46286 | P30: =IF(D30="Open",KPI!$K$13-B30,"") | Q30: =IF(P30="","",IF(P30>K30,"Yes","No"))
A31: CS-1030 | B31: 46271 | C31: 46277 | D31: Closed | E31: P2 | F31: Customer inquiry | G31: Fab A | H31: Lin | I31: Waiting for parts | K31: =_xlfn.XLOOKUP(Cases_Tbl[[#This Row],[Priority]],SLA_Table!$A$2:$A$4,SLA_Table!$B$2:$B$4) -> 5 | L31: =IF(OR(C31="",J31<>""),"",C31-B31) -> 6 | M31: =IF(L31="","",IF(L31<=K31,"Yes","No")) -> No | N31: =B31-WEEKDAY(B31,2)+1 -> 46265 | O31: =IF(C31="","",C31-WEEKDAY(C31,2)+1) -> 46272 | P31: =IF(D31="Open",KPI!$K$13-B31,"") | Q31: =IF(P31="","",IF(P31>K31,"Yes","No"))
A32: CS-1031 | B32: 46272 | C32: 46280 | D32: Closed | E32: P3 | F32: Part replacement | G32: Fab A | H32: Wang | K32: =_xlfn.XLOOKUP(Cases_Tbl[[#This Row],[Priority]],SLA_Table!$A$2:$A$4,SLA_Table!$B$2:$B$4) -> 10 | L32: =IF(OR(C32="",J32<>""),"",C32-B32) -> 8 | M32: =IF(L32="","",IF(L32<=K32,"Yes","No")) -> Yes | N32: =B32-WEEKDAY(B32,2)+1 -> 46272 | O32: =IF(C32="","",C32-WEEKDAY(C32,2)+1) -> 46279 | P32: =IF(D32="Open",KPI!$K$13-B32,"") | Q32: =IF(P32="","",IF(P32>K32,"Yes","No"))
A33: CS-1032 | B33: 46272 | C33: 46278 | D33: Closed | E33: P3 | F33: Part replacement | G33: Fab C | H33: Lin | K33: =_xlfn.XLOOKUP(Cases_Tbl[[#This Row],[Priority]],SLA_Table!$A$2:$A$4,SLA_Table!$B$2:$B$4) -> 10 | L33: =IF(OR(C33="",J33<>""),"",C33-B33) -> 6 | M33: =IF(L33="","",IF(L33<=K33,"Yes","No")) -> Yes | N33: =B33-WEEKDAY(B33,2)+1 -> 46272 | O33: =IF(C33="","",C33-WEEKDAY(C33,2)+1) -> 46272 | P33: =IF(D33="Open",KPI!$K$13-B33,"") | Q33: =IF(P33="","",IF(P33>K33,"Yes","No"))
A34: CS-1033 | B34: 46272 | C34: 46276 | D34: Closed | E34: P2 | F34: Part replacement | G34: Fab A | H34: Tsai | K34: =_xlfn.XLOOKUP(Cases_Tbl[[#This Row],[Priority]],SLA_Table!$A$2:$A$4,SLA_Table!$B$2:$B$4) -> 5 | L34: =IF(OR(C34="",J34<>""),"",C34-B34) -> 4 | M34: =IF(L34="","",IF(L34<=K34,"Yes","No")) -> Yes | N34: =B34-WEEKDAY(B34,2)+1 -> 46272 | O34: =IF(C34="","",C34-WEEKDAY(C34,2)+1) -> 46272 | P34: =IF(D34="Open",KPI!$K$13-B34,"") | Q34: =IF(P34="","",IF(P34>K34,"Yes","No"))
A35: CS-1034 | B35: 46272 | C35: 46277 | D35: Closed | E35: P2 | F35: Part replacement | G35: Fab B | H35: Liu | K35: =_xlfn.XLOOKUP(Cases_Tbl[[#This Row],[Priority]],SLA_Table!$A$2:$A$4,SLA_Table!$B$2:$B$4) -> 5 | L35: =IF(OR(C35="",J35<>""),"",C35-B35) -> 5 | M35: =IF(L35="","",IF(L35<=K35,"Yes","No")) -> Yes | N35: =B35-WEEKDAY(B35,2)+1 -> 46272 | O35: =IF(C35="","",C35-WEEKDAY(C35,2)+1) -> 46272 | P35: =IF(D35="Open",KPI!$K$13-B35,"") | Q35: =IF(P35="","",IF(P35>K35,"Yes","No"))
A36: CS-1035 | B36: 46272 | C36: 46273 | D36: Closed | E36: P1 | F36: Customer inquiry | G36: Fab A | H36: Lin | K36: =_xlfn.XLOOKUP(Cases_Tbl[[#This Row],[Priority]],SLA_Table!$A$2:$A$4,SLA_Table!$B$2:$B$4) -> 2 | L36: =IF(OR(C36="",J36<>""),"",C36-B36) -> 1 | M36: =IF(L36="","",IF(L36<=K36,"Yes","No")) -> Yes | N36: =B36-WEEKDAY(B36,2)+1 -> 46272 | O36: =IF(C36="","",C36-WEEKDAY(C36,2)+1) -> 46272 | P36: =IF(D36="Open",KPI!$K$13-B36,"") | Q36: =IF(P36="","",IF(P36>K36,"Yes","No"))
A37: CS-1036 | B37: 46272 | C37: 46273 | D37: Closed | E37: P1 | F37: Unscheduled repair | G37: Fab C | H37: Wang | K37: =_xlfn.XLOOKUP(Cases_Tbl[[#This Row],[Priority]],SLA_Table!$A$2:$A$4,SLA_Table!$B$2:$B$4) -> 2 | L37: =IF(OR(C37="",J37<>""),"",C37-B37) -> 1 | M37: =IF(L37="","",IF(L37<=K37,"Yes","No")) -> Yes | N37: =B37-WEEKDAY(B37,2)+1 -> 46272 | O37: =IF(C37="","",C37-WEEKDAY(C37,2)+1) -> 46272 | P37: =IF(D37="Open",KPI!$K$13-B37,"") | Q37: =IF(P37="","",IF(P37>K37,"Yes","No"))
A38: CS-1037 | B38: 46273 | C38: 46288 | D38: Closed | E38: P3 | F38: Customer inquiry | G38: Fab B | H38: Chen | I38: Escalated to tech support | K38: =_xlfn.XLOOKUP(Cases_Tbl[[#This Row],[Priority]],SLA_Table!$A$2:$A$4,SLA_Table!$B$2:$B$4) -> 10 | L38: =IF(OR(C38="",J38<>""),"",C38-B38) -> 15 | M38: =IF(L38="","",IF(L38<=K38,"Yes","No")) -> No | N38: =B38-WEEKDAY(B38,2)+1 -> 46272 | O38: =IF(C38="","",C38-WEEKDAY(C38,2)+1) -> 46286 | P38: =IF(D38="Open",KPI!$K$13-B38,"") | Q38: =IF(P38="","",IF(P38>K38,"Yes","No"))
A39: CS-1038 | B39: 46273 | C39: 46280 | D39: Closed | E39: P3 | F39: Customer inquiry | G39: Fab B | H39: Huang | K39: =_xlfn.XLOOKUP(Cases_Tbl[[#This Row],[Priority]],SLA_Table!$A$2:$A$4,SLA_Table!$B$2:$B$4) -> 10 | L39: =IF(OR(C39="",J39<>""),"",C39-B39) -> 7 | M39: =IF(L39="","",IF(L39<=K39,"Yes","No")) -> Yes | N39: =B39-WEEKDAY(B39,2)+1 -> 46272 | O39: =IF(C39="","",C39-WEEKDAY(C39,2)+1) -> 46279 | P39: =IF(D39="Open",KPI!$K$13-B39,"") | Q39: =IF(P39="","",IF(P39>K39,"Yes","No"))
A40: CS-1039 | B40: 46273 | C40: 46277 | D40: Closed | E40: P2 | F40: Part replacement | G40: Fab A | H40: Tsai | K40: =_xlfn.XLOOKUP(Cases_Tbl[[#This Row],[Priority]],SLA_Table!$A$2:$A$4,SLA_Table!$B$2:$B$4) -> 5 | L40: =IF(OR(C40="",J40<>""),"",C40-B40) -> 4 | M40: =IF(L40="","",IF(L40<=K40,"Yes","No")) -> Yes | N40: =B40-WEEKDAY(B40,2)+1 -> 46272 | O40: =IF(C40="","",C40-WEEKDAY(C40,2)+1) -> 46272 | P40: =IF(D40="Open",KPI!$K$13-B40,"") | Q40: =IF(P40="","",IF(P40>K40,"Yes","No"))
...

Sheet Cleaning_Log
A1: 欄位（問題出在哪一欄） | B1: 問題（看到什麼不對） | C1: 影響筆數 | D1: 處理方式
A2: Priority | B2: 寫法不一致：小寫、尾端多空格、寫成 Priority 3 | C2: 5 | D2: 用 EXACT 公式找出非標準寫法，手動改為 P1／P2／P3
A3: Owner | B3: 負責人空白 | C3: 6 | D3: 填入 Unassigned，標記為需向團隊確認，不自行推測負責人
A4: Owner | B4: 名字尾端多空格，同一人會被算成兩人 | C4: 5 | D4: 用 EXACT＋TRIM 公式找出，重新輸入正確名字
A5: Open_Date | B5: 日期存成文字，且格式不一（年/月/日、月-日-年、日.月.年），無法計算天數 | C5: 9 | D5: 用 ISNUMBER 找出文字日期，依資料期間判斷日月順序後改成標準日期
A6: Delay_Reason | B6: 同一原因有多種寫法：簡寫、小寫、尾端空格 | C6: 8 | D6: 以 4 種標準分類為準，用公式找出非標準值後統一改寫
A7: Case_ID | B7: 同一案件重複輸入，會讓開案數與逾期率偏高 | C7: 6 | D7: 用 COUNTIF 累計次數找出第二次出現的列，確認整列內容相同後刪除，保留第一筆
A8: Open_Date / Close_Date | B8: 結案日早於開案日 | C8: 3 | D8: 無法判斷哪個日期錯，不自行修改；新增 Data_Flag 標記為待確認，計算處理天數時排除
